2019-03-16 12:36:58,867 ERROR: Exception on /user/dog [GET] [in c:\users\penga_000\desktop\python_projects\flask_app\microblog\venv\lib\site-packages\flask\app.py:1761]
Traceback (most recent call last):
  File "c:\users\penga_000\desktop\python_projects\flask_app\microblog\venv\lib\site-packages\flask\app.py", line 2292, in wsgi_app
    response = self.full_dispatch_request()
  File "c:\users\penga_000\desktop\python_projects\flask_app\microblog\venv\lib\site-packages\flask\app.py", line 1815, in full_dispatch_request
    rv = self.handle_user_exception(e)
  File "c:\users\penga_000\desktop\python_projects\flask_app\microblog\venv\lib\site-packages\flask\app.py", line 1718, in handle_user_exception
    reraise(exc_type, exc_value, tb)
  File "c:\users\penga_000\desktop\python_projects\flask_app\microblog\venv\lib\site-packages\flask\_compat.py", line 35, in reraise
    raise value
  File "c:\users\penga_000\desktop\python_projects\flask_app\microblog\venv\lib\site-packages\flask\app.py", line 1813, in full_dispatch_request
    rv = self.dispatch_request()
  File "c:\users\penga_000\desktop\python_projects\flask_app\microblog\venv\lib\site-packages\flask\app.py", line 1799, in dispatch_request
    return self.view_functions[rule.endpoint](**req.view_args)
  File "c:\users\penga_000\desktop\python_projects\flask_app\microblog\venv\lib\site-packages\flask_login\utils.py", line 261, in decorated_view
    return func(*args, **kwargs)
  File "C:\Users\penga_000\Desktop\python_projects\flask_app\microblog\app\routes.py", line 70, in user
    return render_template('user.html', user=user, posts=posts)
  File "c:\users\penga_000\desktop\python_projects\flask_app\microblog\venv\lib\site-packages\flask\templating.py", line 135, in render_template
    context, ctx.app)
  File "c:\users\penga_000\desktop\python_projects\flask_app\microblog\venv\lib\site-packages\flask\templating.py", line 117, in _render
    rv = template.render(context)
  File "c:\users\penga_000\desktop\python_projects\flask_app\microblog\venv\lib\site-packages\jinja2\asyncsupport.py", line 76, in render
    return original_render(self, *args, **kwargs)
  File "c:\users\penga_000\desktop\python_projects\flask_app\microblog\venv\lib\site-packages\jinja2\environment.py", line 1008, in render
    return self.environment.handle_exception(exc_info, True)
  File "c:\users\penga_000\desktop\python_projects\flask_app\microblog\venv\lib\site-packages\jinja2\environment.py", line 780, in handle_exception
    reraise(exc_type, exc_value, tb)
  File "c:\users\penga_000\desktop\python_projects\flask_app\microblog\venv\lib\site-packages\jinja2\_compat.py", line 37, in reraise
    raise value.with_traceback(tb)
  File "C:\Users\penga_000\Desktop\python_projects\flask_app\microblog\app\templates\user.html", line 1, in top-level template code
    {% extends "base.html" %}
  File "C:\Users\penga_000\Desktop\python_projects\flask_app\microblog\app\templates\base.html", line 31, in top-level template code
    {% block content %}{% endblock %}
  File "C:\Users\penga_000\Desktop\python_projects\flask_app\microblog\app\templates\user.html", line 14, in block "content"
    {% elif not current_user.is_following(user) %}
  File "C:\Users\penga_000\Desktop\python_projects\flask_app\microblog\app\models.py", line 49, in is_following
    self.followers.c.followed_id == user.id).count() > 0
AttributeError: 'AppenderBaseQuery' object has no attribute 'c'
2019-03-16 12:37:19,647 ERROR: Exception on /user/cat [GET] [in c:\users\penga_000\desktop\python_projects\flask_app\microblog\venv\lib\site-packages\flask\app.py:1761]
Traceback (most recent call last):
  File "c:\users\penga_000\desktop\python_projects\flask_app\microblog\venv\lib\site-packages\flask\app.py", line 2292, in wsgi_app
    response = self.full_dispatch_request()
  File "c:\users\penga_000\desktop\python_projects\flask_app\microblog\venv\lib\site-packages\flask\app.py", line 1815, in full_dispatch_request
    rv = self.handle_user_exception(e)
  File "c:\users\penga_000\desktop\python_projects\flask_app\microblog\venv\lib\site-packages\flask\app.py", line 1718, in handle_user_exception
    reraise(exc_type, exc_value, tb)
  File "c:\users\penga_000\desktop\python_projects\flask_app\microblog\venv\lib\site-packages\flask\_compat.py", line 35, in reraise
    raise value
  File "c:\users\penga_000\desktop\python_projects\flask_app\microblog\venv\lib\site-packages\flask\app.py", line 1813, in full_dispatch_request
    rv = self.dispatch_request()
  File "c:\users\penga_000\desktop\python_projects\flask_app\microblog\venv\lib\site-packages\flask\app.py", line 1799, in dispatch_request
    return self.view_functions[rule.endpoint](**req.view_args)
  File "c:\users\penga_000\desktop\python_projects\flask_app\microblog\venv\lib\site-packages\flask_login\utils.py", line 261, in decorated_view
    return func(*args, **kwargs)
  File "C:\Users\penga_000\Desktop\python_projects\flask_app\microblog\app\routes.py", line 70, in user
    return render_template('user.html', user=user, posts=posts)
  File "c:\users\penga_000\desktop\python_projects\flask_app\microblog\venv\lib\site-packages\flask\templating.py", line 135, in render_template
    context, ctx.app)
  File "c:\users\penga_000\desktop\python_projects\flask_app\microblog\venv\lib\site-packages\flask\templating.py", line 117, in _render
    rv = template.render(context)
  File "c:\users\penga_000\desktop\python_projects\flask_app\microblog\venv\lib\site-packages\jinja2\asyncsupport.py", line 76, in render
    return original_render(self, *args, **kwargs)
  File "c:\users\penga_000\desktop\python_projects\flask_app\microblog\venv\lib\site-packages\jinja2\environment.py", line 1008, in render
    return self.environment.handle_exception(exc_info, True)
  File "c:\users\penga_000\desktop\python_projects\flask_app\microblog\venv\lib\site-packages\jinja2\environment.py", line 780, in handle_exception
    reraise(exc_type, exc_value, tb)
  File "c:\users\penga_000\desktop\python_projects\flask_app\microblog\venv\lib\site-packages\jinja2\_compat.py", line 37, in reraise
    raise value.with_traceback(tb)
  File "C:\Users\penga_000\Desktop\python_projects\flask_app\microblog\app\templates\user.html", line 1, in top-level template code
    {% extends "base.html" %}
  File "C:\Users\penga_000\Desktop\python_projects\flask_app\microblog\app\templates\base.html", line 31, in top-level template code
    {% block content %}{% endblock %}
  File "C:\Users\penga_000\Desktop\python_projects\flask_app\microblog\app\templates\user.html", line 14, in block "content"
    {% elif not current_user.is_following(user) %}
  File "C:\Users\penga_000\Desktop\python_projects\flask_app\microblog\app\models.py", line 49, in is_following
    self.followers.c.followed_id == user.id).count() > 0
AttributeError: 'AppenderBaseQuery' object has no attribute 'c'
