2019-03-16 13:07:59,714 ERROR: Exception on /user/dog [GET] [in c:\users\penga_000\desktop\python_projects\flask_app\microblog\venv\lib\site-packages\flask\app.py:1761]
Traceback (most recent call last):
  File "c:\users\penga_000\desktop\python_projects\flask_app\microblog\venv\lib\site-packages\flask\app.py", line 2292, in wsgi_app
    response = self.full_dispatch_request()
  File "c:\users\penga_000\desktop\python_projects\flask_app\microblog\venv\lib\site-packages\flask\app.py", line 1815, in full_dispatch_request
    rv = self.handle_user_exception(e)
  File "c:\users\penga_000\desktop\python_projects\flask_app\microblog\venv\lib\site-packages\flask\app.py", line 1718, in handle_user_exception
    reraise(exc_type, exc_value, tb)
  File "c:\users\penga_000\desktop\python_projects\flask_app\microblog\venv\lib\site-packages\flask\_compat.py", line 35, in reraise
    raise value
  File "c:\users\penga_000\desktop\python_projects\flask_app\microblog\venv\lib\site-packages\flask\app.py", line 1813, in full_dispatch_request
    rv = self.dispatch_request()
  File "c:\users\penga_000\desktop\python_projects\flask_app\microblog\venv\lib\site-packages\flask\app.py", line 1799, in dispatch_request
    return self.view_functions[rule.endpoint](**req.view_args)
  File "c:\users\penga_000\desktop\python_projects\flask_app\microblog\venv\lib\site-packages\flask_login\utils.py", line 261, in decorated_view
    return func(*args, **kwargs)
  File "C:\Users\penga_000\Desktop\python_projects\flask_app\microblog\app\routes.py", line 70, in user
    return render_template('user.html', user=user, posts=posts)
  File "c:\users\penga_000\desktop\python_projects\flask_app\microblog\venv\lib\site-packages\flask\templating.py", line 135, in render_template
    context, ctx.app)
  File "c:\users\penga_000\desktop\python_projects\flask_app\microblog\venv\lib\site-packages\flask\templating.py", line 117, in _render
    rv = template.render(context)
  File "c:\users\penga_000\desktop\python_projects\flask_app\microblog\venv\lib\site-packages\jinja2\asyncsupport.py", line 76, in render
    return original_render(self, *args, **kwargs)
  File "c:\users\penga_000\desktop\python_projects\flask_app\microblog\venv\lib\site-packages\jinja2\environment.py", line 1008, in render
    return self.environment.handle_exception(exc_info, True)
  File "c:\users\penga_000\desktop\python_projects\flask_app\microblog\venv\lib\site-packages\jinja2\environment.py", line 780, in handle_exception
    reraise(exc_type, exc_value, tb)
  File "c:\users\penga_000\desktop\python_projects\flask_app\microblog\venv\lib\site-packages\jinja2\_compat.py", line 37, in reraise
    raise value.with_traceback(tb)
  File "C:\Users\penga_000\Desktop\python_projects\flask_app\microblog\app\templates\user.html", line 1, in top-level template code
    {% extends "base.html" %}
  File "C:\Users\penga_000\Desktop\python_projects\flask_app\microblog\app\templates\base.html", line 31, in top-level template code
    {% block content %}{% endblock %}
  File "C:\Users\penga_000\Desktop\python_projects\flask_app\microblog\app\templates\user.html", line 14, in block "content"
    {% elif not current_user.is_following(user) %}
  File "C:\Users\penga_000\Desktop\python_projects\flask_app\microblog\app\models.py", line 49, in is_following
    self.followers.c.followed_id == user.id).count() > 0
AttributeError: 'AppenderBaseQuery' object has no attribute 'c'
2019-03-16 13:08:52,142 INFO: Microblog startup [in C:\Users\penga_000\Desktop\python_projects\flask_app\microblog\app\__init__.py:45]
2019-03-16 13:11:19,073 INFO: Microblog startup [in C:\Users\penga_000\Desktop\python_projects\flask_app\microblog\app\__init__.py:45]
2019-03-16 13:11:29,756 INFO: Microblog startup [in C:\Users\penga_000\Desktop\python_projects\flask_app\microblog\app\__init__.py:45]
2019-03-16 13:11:39,534 INFO: Microblog startup [in C:\Users\penga_000\Desktop\python_projects\flask_app\microblog\app\__init__.py:45]
2019-03-16 13:16:01,381 INFO: Microblog startup [in C:\Users\penga_000\Desktop\python_projects\flask_app\microblog\app\__init__.py:45]
2019-03-16 13:16:29,993 INFO: Microblog startup [in C:\Users\penga_000\Desktop\python_projects\flask_app\microblog\app\__init__.py:45]
2019-03-16 13:16:51,252 INFO: Microblog startup [in C:\Users\penga_000\Desktop\python_projects\flask_app\microblog\app\__init__.py:45]
2019-03-16 13:17:09,951 INFO: Microblog startup [in C:\Users\penga_000\Desktop\python_projects\flask_app\microblog\app\__init__.py:45]
2019-03-16 13:17:55,995 INFO: Microblog startup [in C:\Users\penga_000\Desktop\python_projects\flask_app\microblog\app\__init__.py:45]
2019-03-16 13:27:17,450 INFO: Microblog startup [in C:\Users\penga_000\Desktop\python_projects\flask_app\microblog\app\__init__.py:45]
2019-03-16 13:31:23,467 INFO: Microblog startup [in C:\Users\penga_000\Desktop\python_projects\flask_app\microblog\app\__init__.py:45]
2019-03-16 13:31:54,921 INFO: Microblog startup [in C:\Users\penga_000\Desktop\python_projects\flask_app\microblog\app\__init__.py:45]
2019-03-16 13:32:07,667 INFO: Microblog startup [in C:\Users\penga_000\Desktop\python_projects\flask_app\microblog\app\__init__.py:45]
2019-03-16 13:33:22,246 INFO: Microblog startup [in C:\Users\penga_000\Desktop\python_projects\flask_app\microblog\app\__init__.py:45]
2019-03-16 13:34:21,584 INFO: Microblog startup [in C:\Users\penga_000\Desktop\python_projects\flask_app\microblog\app\__init__.py:45]
2019-03-16 13:34:32,429 INFO: Microblog startup [in C:\Users\penga_000\Desktop\python_projects\flask_app\microblog\app\__init__.py:45]
2019-03-16 13:48:40,756 INFO: Microblog startup [in C:\Users\penga_000\Desktop\python_projects\flask_app\microblog\app\__init__.py:45]
2019-03-16 13:50:15,397 INFO: Microblog startup [in C:\Users\penga_000\Desktop\python_projects\flask_app\microblog\app\__init__.py:45]
2019-03-16 13:50:21,357 INFO: Microblog startup [in C:\Users\penga_000\Desktop\python_projects\flask_app\microblog\app\__init__.py:45]
2019-03-16 13:51:22,765 INFO: Microblog startup [in C:\Users\penga_000\Desktop\python_projects\flask_app\microblog\app\__init__.py:45]
2019-03-16 13:53:40,492 INFO: Microblog startup [in C:\Users\penga_000\Desktop\python_projects\flask_app\microblog\app\__init__.py:45]
2019-03-16 14:28:26,967 INFO: Microblog startup [in C:\Users\penga_000\Desktop\python_projects\flask_app\microblog\app\__init__.py:45]
2019-03-16 15:09:22,453 INFO: Microblog startup [in C:\Users\penga_000\Desktop\python_projects\flask_app\microblog\app\__init__.py:45]
2019-03-16 15:27:28,721 INFO: Microblog startup [in C:\Users\penga_000\Desktop\python_projects\flask_app\microblog\app\__init__.py:47]
2019-03-16 15:32:16,119 INFO: Microblog startup [in C:\Users\penga_000\Desktop\python_projects\flask_app\microblog\app\__init__.py:47]
2019-03-16 15:38:12,000 INFO: Microblog startup [in C:\Users\penga_000\Desktop\python_projects\flask_app\microblog\app\__init__.py:47]
2019-03-23 13:24:18,319 INFO: Microblog startup [in C:\Users\penga_000\Desktop\python_projects\flask_app\microblog\app\__init__.py:45]
2019-03-23 13:43:00,456 INFO: Microblog startup [in C:\Users\penga_000\Desktop\python_projects\flask_app\microblog\app\__init__.py:45]
2019-03-23 13:44:48,232 INFO: Microblog startup [in C:\Users\penga_000\Desktop\python_projects\flask_app\microblog\app\__init__.py:45]
2019-03-23 13:51:01,500 INFO: Microblog startup [in C:\Users\penga_000\Desktop\python_projects\flask_app\microblog\app\__init__.py:47]
2019-03-23 13:53:05,798 INFO: Microblog startup [in C:\Users\penga_000\Desktop\python_projects\flask_app\microblog\app\__init__.py:47]
2019-03-23 13:53:43,246 INFO: Microblog startup [in C:\Users\penga_000\Desktop\python_projects\flask_app\microblog\app\__init__.py:45]
2019-03-23 15:02:42,240 INFO: Microblog startup [in C:\Users\penga_000\Desktop\python_projects\flask_app\microblog\app\__init__.py:45]
2019-03-23 15:04:45,230 INFO: Microblog startup [in C:\Users\penga_000\Desktop\python_projects\flask_app\microblog\app\__init__.py:45]
2019-03-23 15:05:09,636 ERROR: Exception on /reset_password_request [POST] [in c:\users\penga_000\desktop\python_projects\flask_app\microblog\venv\lib\site-packages\flask\app.py:1761]
Traceback (most recent call last):
  File "c:\users\penga_000\desktop\python_projects\flask_app\microblog\venv\lib\site-packages\flask\app.py", line 2292, in wsgi_app
    response = self.full_dispatch_request()
  File "c:\users\penga_000\desktop\python_projects\flask_app\microblog\venv\lib\site-packages\flask\app.py", line 1815, in full_dispatch_request
    rv = self.handle_user_exception(e)
  File "c:\users\penga_000\desktop\python_projects\flask_app\microblog\venv\lib\site-packages\flask\app.py", line 1718, in handle_user_exception
    reraise(exc_type, exc_value, tb)
  File "c:\users\penga_000\desktop\python_projects\flask_app\microblog\venv\lib\site-packages\flask\_compat.py", line 35, in reraise
    raise value
  File "c:\users\penga_000\desktop\python_projects\flask_app\microblog\venv\lib\site-packages\flask\app.py", line 1813, in full_dispatch_request
    rv = self.dispatch_request()
  File "c:\users\penga_000\desktop\python_projects\flask_app\microblog\venv\lib\site-packages\flask\app.py", line 1799, in dispatch_request
    return self.view_functions[rule.endpoint](**req.view_args)
  File "C:\Users\penga_000\Desktop\python_projects\flask_app\microblog\app\routes.py", line 156, in reset_password_request
    app.email.send_password_reset_email(user)
AttributeError: 'Flask' object has no attribute 'email'
2019-03-23 15:08:42,089 INFO: Microblog startup [in C:\Users\penga_000\Desktop\python_projects\flask_app\microblog\app\__init__.py:45]
